Workbook

Sheet Posts
A1: Post ID | B1: Platform | C1: Date | D1: Content Type | E1: Post Text | F1: Likes | G1: Shares | H1: Comments | I1: Impressions | J1: Reach | K1: Clicks | L1: Hashtag 1 | M1: Hashtag 2 | N1: Campaign_Name | O1: Engagement Rate
A2: SP001 | B2: Instagram | C2: 45781 | D2: Text | E2: Discover fresh beats on Spotify! | F2: 2414 | G2: 245 | H2: 137 | I2: 21181 | J2: 45292 | K2: 133 | L2: #SoundtrackOfLife | M2: #NowPlaying | N2: ChillVibes | O2: 0.1320051
A3: SP002 | B3: Instagram | C3: 45689 | D3: Text | E3: Explore the latest podcasts now. | F3: 1934 | G3: 210 | H3: 393 | I3: 29129 | J3: 73287 | K3: 273 | L3: #DiscoverWeekly | N3: IndieWave | O3: 0.087095335
A4: SP003 | B4: Twitter | C4: 45629 | D4: Story | E4: New music just dropped. Hit play! | F4: 3092 | G4: 177 | H4: 81 | I4: 47533 | J4: 29220 | K4: 121 | L4: #MusicForEveryone | M4: #NowPlaying | N4: ChillVibes | O4: 0.070477353
A5: SP004 | B5: Instagram | C5: 45629 | D5: Text | E5: Wrapped is here! Relive your top tracks ðŸŽ§ | F5: 3173 | G5: 229 | H5: 197 | I5: 29604 | J5: 21809 | K5: 272 | L5: #SoundtrackOfLife | M5: #NowPlaying | N5: ChillVibes | O5: 0.12157141
A6: SP005 | B6: YouTube | C6: 45388 | D6: Text | E6: Music that moves youâ€”only on Spotify. | F6: 2748 | G6: 145 | H6: 315 | I6: 24401 | J6: 61182 | K6: 200 | L6: #DiscoverWeekly | M6: #SpotifyWrapped | N6: IndieWave | O6: 0.13147002
A7: SP006 | B7: YouTube | C7: 45456 | D7: Text | E7: Whatâ€™s your vibe today? #SpotifyHits | F7: 3882 | G7: 239 | H7: 275 | I7: 58748 | J7: 44646 | K7: 149 | L7: #DiscoverWeekly | M7: #SpotifyWrapped | N7: IndieWave | O7: 0.074828079
A8: SP007 | B8: Twitter | C8: 45645 | D8: Story | E8: Get into the groove with our new drop! | F8: 4674 | G8: 409 | H8: 327 | I8: 20756 | J8: 63599 | K8: 212 | L8: #SoundtrackOfLife | M8: #NowPlaying | N8: ChillVibes | O8: 0.26064752
A9: SP008 | B9: Twitter | C9: 45421 | D9: Story | E9: Wrapped is here! Relive your top tracks ðŸŽ§ | F9: 1428 | G9: 347 | H9: 67 | I9: 21148 | J9: 19712 | K9: 120 | L9: #DiscoverWeekly | M9: #MusicForEveryone | N9: ChillVibes | O9: 0.087100435
A10: SP009 | B10: Twitter | C10: 45823 | D10: Text | E10: Top trending tracks updated daily! | F10: 4432 | G10: 223 | H10: 299 | I10: 59016 | J10: 21742 | K10: 171 | L10: #NowPlaying | N10: ChillVibes | O10: 0.083943337
A11: SP010 | B11: Twitter | C11: 45630 | D11: Text | E11: Wrapped is here! Relive your top tracks ðŸŽ§ | F11: 2357 | G11: 274 | H11: 172 | I11: 21566 | J11: 66829 | K11: 284 | L11: #NowPlaying | N11: ChillVibes | O11: 0.12997311
A12: SP011 | B12: Twitter | C12: 45357 | D12: Text | E12: Discover fresh beats on Spotify! | F12: 1971 | G12: 370 | H12: 306 | I12: 31316 | J12: 27897 | K12: 88 | L12: #SoundtrackOfLife | N12: IndieWave | O12: 0.084525482
A13: SP012 | B13: Instagram | C13: 45426 | D13: Text | E13: Discover fresh beats on Spotify! | F13: 1485 | G13: 353 | H13: 244 | I13: 38419 | J13: 38556 | K13: 86 | L13: #SoundtrackOfLife | M13: #NowPlaying | N13: ChillVibes | O13: 0.054191936
A14: SP013 | B14: Twitter | C14: 45826 | D14: Story | E14: Discover fresh beats on Spotify! | F14: 3956 | G14: 319 | H14: 61 | I14: 58162 | J14: 28720 | K14: 213 | L14: #MusicForEveryone | M14: #NowPlaying | N14: ChillVibes | O14: 0.074550394
A15: SP014 | B15: Twitter | C15: 45573 | D15: Text | E15: From pop to podcasts, itâ€™s all here. | F15: 2460 | G15: 409 | H15: 253 | I15: 36702 | J15: 46122 | K15: 264 | L15: #NowPlaying | N15: ChillVibes | O15: 0.085063484
A16: SP015 | B16: Twitter | C16: 45418 | D16: Text | E16: Your weekend playlist is waiting. | F16: 3476 | G16: 355 | H16: 396 | I16: 37492 | J16: 27285 | K16: 179 | L16: #NowPlaying | N16: ChillVibes | O16: 0.11274405
A17: SP016 | B17: Twitter | C17: 45655 | D17: Story | E17: New music just dropped. Hit play! | F17: 4049 | G17: 377 | H17: 94 | I17: 48182 | J17: 42875 | K17: 172 | L17: #MusicForEveryone | M17: #NowPlaying | N17: ChillVibes | O17: 0.093810967
A18: SP017 | B18: Twitter | C18: 45453 | D18: Text | E18: Whatâ€™s your vibe today? #SpotifyHits | F18: 1514 | G18: 164 | H18: 275 | I18: 41364 | J18: 44389 | K18: 83 | L18: #NowPlaying | N18: ChillVibes | O18: 0.04721497
A19: SP018 | B19: Instagram | C19: 45325 | D19: Story | E19: Music that moves youâ€”only on Spotify. | F19: 4281 | G19: 101 | H19: 163 | I19: 32278 | J19: 53382 | K19: 235 | L19: #NowPlaying | N19: Wrapped2024 | O19: 0.14080798
A20: SP019 | B20: YouTube | C20: 45458 | D20: Reel | E20: Get into the groove with our new drop! | F20: 1751 | G20: 143 | H20: 151 | I20: 31826 | J20: 47729 | K20: 95 | L20: #DiscoverWeekly | M20: #SoundtrackOfLife | N20: SummerBeats | O20: 0.06425564
A21: SP020 | B21: Instagram | C21: 45478 | D21: Text | E21: Your weekend playlist is waiting. | F21: 3753 | G21: 411 | H21: 308 | I21: 29138 | J21: 27678 | K21: 90 | L21: #DiscoverWeekly | N21: IndieWave | O21: 0.15347656
A22: SP021 | B22: Instagram | C22: 45603 | D22: Story | E22: Wrapped is here! Relive your top tracks ðŸŽ§ | F22: 1678 | G22: 423 | H22: 323 | I22: 55668 | J22: 37945 | K22: 230 | L22: #NowPlaying | N22: Wrapped2024 | O22: 0.043543867
A23: SP022 | B23: Instagram | C23: 45823 | D23: Text | E23: Whatâ€™s your vibe today? #SpotifyHits | F23: 4896 | G23: 466 | H23: 233 | I23: 28621 | J23: 34270 | K23: 84 | L23: #SoundtrackOfLife | M23: #NowPlaying | N23: ChillVibes | O23: 0.19548583
A24: SP023 | B24: YouTube | C24: 45452 | D24: Reel | E24: From pop to podcasts, itâ€™s all here. | F24: 2786 | G24: 368 | H24: 208 | I24: 42000 | J24: 39967 | K24: 103 | L24: #DiscoverWeekly | M24: #SoundtrackOfLife | N24: SummerBeats | O24: 0.080047619
A25: SP024 | B25: Twitter | C25: 45583 | D25: Text | E25: New music just dropped. Hit play! | F25: 2607 | G25: 379 | H25: 180 | I25: 28712 | J25: 61620 | K25: 174 | L25: #SoundtrackOfLife | N25: IndieWave | O25: 0.11026748
A26: SP025 | B26: YouTube | C26: 45575 | D26: Reel | E26: From pop to podcasts, itâ€™s all here. | F26: 4013 | G26: 320 | H26: 92 | I26: 54605 | J26: 60169 | K26: 232 | L26: #DiscoverWeekly | M26: #SoundtrackOfLife | N26: SummerBeats | O26: 0.081036535
A27: SP026 | B27: Twitter | C27: 45791 | D27: Story | E27: From pop to podcasts, itâ€™s all here. | F27: 2707 | G27: 103 | H27: 51 | I27: 55302 | J27: 18801 | K27: 147 | L27: #DiscoverWeekly | M27: #MusicForEveryone | N27: ChillVibes | O27: 0.051734114
A28: SP027 | B28: Instagram | C28: 45625 | D28: Text | E28: Whatâ€™s your vibe today? #SpotifyHits | F28: 2824 | G28: 425 | H28: 274 | I28: 31004 | J28: 53488 | K28: 268 | L28: #SoundtrackOfLife | M28: #NowPlaying | N28: ChillVibes | O28: 0.1136305
A29: SP028 | B29: YouTube | C29: 45356 | D29: Reel | E29: Explore the latest podcasts now. | F29: 3558 | G29: 314 | H29: 199 | I29: 49612 | J29: 53929 | K29: 206 | L29: #DiscoverWeekly | M29: #SoundtrackOfLife | N29: SummerBeats | O29: 0.08205676
A30: SP029 | B30: Twitter | C30: 45734 | D30: Story | E30: Explore the latest podcasts now. | F30: 3418 | G30: 188 | H30: 387 | I30: 57431 | J30: 36933 | K30: 202 | L30: #MusicForEveryone | M30: #NowPlaying | N30: ChillVibes | O30: 0.069526911
A31: SP030 | B31: Twitter | C31: 45773 | D31: Text | E31: Discover fresh beats on Spotify! | F31: 2411 | G31: 194 | H31: 168 | I31: 26665 | J31: 71699 | K31: 197 | L31: #NowPlaying | N31: ChillVibes | O31: 0.103994
A32: SP031 | B32: Instagram | C32: 45658 | D32: Text | E32: New music just dropped. Hit play! | F32: 4036 | G32: 112 | H32: 382 | I32: 56284 | J32: 29440 | K32: 279 | L32: #SoundtrackOfLife | M32: #NowPlaying | N32: ChillVibes | O32: 0.080484685
A33: SP032 | B33: Twitter | C33: 45419 | D33: Story | E33: Explore the latest podcasts now. | F33: 2776 | G33: 307 | H33: 178 | I33: 43365 | J33: 48408 | K33: 138 | L33: #SoundtrackOfLife | M33: #NowPlaying | N33: ChillVibes | O33: 0.075198893
A34: SP033 | B34: Twitter | C34: 45574 | D34: Story | E34: Discover fresh beats on Spotify! | F34: 4929 | G34: 182 | H34: 95 | I34: 32181 | J34: 31084 | K34: 289 | L34: #DiscoverWeekly | M34: #MusicForEveryone | N34: ChillVibes | O34: 0.16177247
A35: SP034 | B35: Instagram | C35: 45666 | D35: Text | E35: New music just dropped. Hit play! | F35: 1015 | G35: 366 | H35: 308 | I35: 38127 | J35: 63790 | K35: 287 | L35: #SoundtrackOfLife | M35: #NowPlaying | N35: ChillVibes | O35: 0.044299315
A36: SP035 | B36: Twitter | C36: 45785 | D36: Story | E36: Your weekend playlist is waiting. | F36: 3316 | G36: 332 | H36: 268 | I36: 40095 | J36: 36913 | K36: 265 | L36: #MusicForEveryone | M36: #NowPlaying | N36: ChillVibes | O36: 0.097668038
A37: SP036 | B37: Instagram | C37: 45416 | D37: Text | E37: Wrapped is here! Relive your top tracks ðŸŽ§ | F37: 2274 | G37: 243 | H37: 222 | I37: 43066 | J37: 59174 | K37: 80 | L37: #DiscoverWeekly | N37: IndieWave | O37: 0.063600056
A38: SP037 | B38: Twitter | C38: 45804 | D38: Story | E38: Explore the latest podcasts now. | F38: 4095 | G38: 385 | H38: 400 | I38: 45300 | J38: 31795 | K38: 80 | L38: #MusicForEveryone | M38: #NowPlaying | N38: ChillVibes | O38: 0.10772627
A39: SP038 | B39: Instagram | C39: 45545 | D39: Story | E39: New music just dropped. Hit play! | F39: 1230 | G39: 309 | H39: 207 | I39: 44629 | J39: 40699 | K39: 195 | L39: #NowPlaying | N39: Wrapped2024 | O39: 0.039122544
A40: SP039 | B40: Instagram | C40: 45621 | D40: Text | E40: From pop to podcasts, itâ€™s all here. | F40: 1341 | G40: 472 | H40: 238 | I40: 51386 | J40: 51706 | K40: 133 | L40: #DiscoverWeekly | N40: IndieWave | O40: 0.039913595
...

Sheet Engagement Summary
A1: Week_Start_Date | B1: Platform | C1: New_Followers | D1: Unfollows | E1: Total_Followers | F1: Engagement_Rate | G1: Ad_Spend | H1: Net Follower Gain | I1: Growth Rate %
A2: 45446 | B2: Instagram | C2: 1402 | D2: 68 | E2: 124562 | F2: 9.92 | G2: 23125 | H2: =C2-D2 -> 1334 | I2: =H2/E2 -> 0.010709526
A3: 45446 | B3: Twitter | C3: 995 | D3: 86 | E3: 227958 | F3: 8.05 | G3: 22788 | H3: =C3-D3 -> 909 | I3: =H3/E3 -> 0.0039875767
A4: 45446 | B4: YouTube | C4: 1472 | D4: 296 | E4: 370242 | F4: 7.72 | G4: 7810 | H4: =C4-D4 -> 1176 | I4: =H4/E4 -> 0.0031763009
A5: 45453 | B5: Instagram | C5: 1018 | D5: 90 | E5: 92474 | F5: 9.4 | G5: 11966 | H5: =C5-D5 -> 928 | I5: =H5/E5 -> 0.010035253
A6: 45453 | B6: Twitter | C6: 1461 | D6: 64 | E6: 328902 | F6: 9.02 | G6: 26298 | H6: =C6-D6 -> 1397 | I6: =H6/E6 -> 0.0042474658
A7: 45453 | B7: YouTube | C7: 545 | D7: 93 | E7: 391621 | F7: 9.96 | G7: 22029 | H7: =C7-D7 -> 452 | I7: =H7/E7 -> 0.0011541771
A8: 45460 | B8: Instagram | C8: 881 | D8: 291 | E8: 95885 | F8: 5.29 | G8: 12391 | H8: =C8-D8 -> 590 | I8: =H8/E8 -> 0.0061532044
A9: 45460 | B9: Twitter | C9: 1414 | D9: 131 | E9: 245947 | F9: 8.3 | G9: 14477 | H9: =C9-D9 -> 1283 | I9: =H9/E9 -> 0.005216571
A10: 45460 | B10: YouTube | C10: 1472 | D10: 170 | E10: 250428 | F10: 4.66 | G10: 25040 | H10: =C10-D10 -> 1302 | I10: =H10/E10 -> 0.0051990991
A11: 45467 | B11: Instagram | C11: 809 | D11: 197 | E11: 87186 | F11: 9.48 | G11: 22619 | H11: =C11-D11 -> 612 | I11: =H11/E11 -> 0.0070194756
A12: 45467 | B12: Twitter | C12: 1371 | D12: 250 | E12: 128620 | F12: 7.11 | G12: 12399 | H12: =C12-D12 -> 1121 | I12: =H12/E12 -> 0.0087155963
A13: 45467 | B13: YouTube | C13: 844 | D13: 144 | E13: 126015 | F13: 9.65 | G13: 22456 | H13: =C13-D13 -> 700 | I13: =H13/E13 -> 0.0055548943
... A201: 45908 | B201: Twitter | C201: 860 | D201: 244 | E201: 348686 | F201: 5.12 | G201: 11418 | H201: =C201-D201 -> 616 | I201: =H201/E201 -> 0.0017666324

Sheet Campaign Metadata
A1: Campaign_Name | B1: Start_Date | C1: End_Date | D1: Objective | E1: Total_Budget | F1: Target_Platforms | G1: Primary_Hashtag_1 | H1: Primary_Hashtag_2
A2: ChillVibes | B2: 45667 | C2: 45698 | D2: Product Launch | E2: 200000 | F2: Instagram,Twitter | G2: #ChillVibes | H2: #SoundtrackOfLife
A3: IndieWave | B3: 45717 | C3: 45747 | D3: Traffic | E3: 160000 | F3: Facebook,Instagram | G3: #DiscoverWeekly | H3: #IndieWave
A4: SummerBeats | B4: 45458 | C4: 45488 | D4: Brand Awareness | E4: 175000 | F4: Instagram,YouTube | G4: #SpotifyWrapped | H4: #MusicForEveryone
A5: Wrapped2024 | B5: 45627 | C5: 45657 | D5: Engagement | E5: 225000 | F5: Twitter,YouTube | G5: #SpotifyWrapped | H5: #NowPlaying

Sheet Hashtag_Master
A1: All_Hashtags | B1: Engagement Rate | C1: Clicks
A2: #SoundtrackOfLife | B2: 0.1320051 | C2: 133
A3: #DiscoverWeekly | B3: 0.087095335 | C3: 273
A4: #MusicForEveryone | B4: 0.070477353 | C4: 121
A5: #SoundtrackOfLife | B5: 0.12157141 | C5: 272
A6: #DiscoverWeekly | B6: 0.13147002 | C6: 200
A7: #DiscoverWeekly | B7: 0.074828079 | C7: 149
A8: #SoundtrackOfLife | B8: 0.26064752 | C8: 212
A9: #DiscoverWeekly | B9: 0.087100435 | C9: 120
A10: #NowPlaying | B10: 0.083943337 | C10: 171
A11: #NowPlaying | B11: 0.12997311 | C11: 284
A12: #SoundtrackOfLife | B12: 0.084525482 | C12: 88
A13: #SoundtrackOfLife | B13: 0.054191936 | C13: 86
... A302: #NowPlaying | B302: 0.1320051 | C302: 133
B303: 0.087095335 | C303: 273
A304: #NowPlaying | B304: 0.070477353 | C304: 121
A305: #NowPlaying | B305: 0.12157141 | C305: 272
A306: #SpotifyWrapped | B306: 0.13147002 | C306: 200
A307: #SpotifyWrapped | B307: 0.074828079 | C307: 149
A308: #NowPlaying | B308: 0.26064752 | C308: 212
A309: #MusicForEveryone | B309: 0.087100435 | C309: 120
B310: 0.083943337 | C310: 171
B311: 0.12997311 | C311: 284
B312: 0.084525482 | C312: 88
A313: #NowPlaying | B313: 0.054191936 | C313: 86
A314: #NowPlaying | B314: 0.074550394 | C314: 213
B315: 0.085063484 | C315: 264
B316: 0.11274405 | C316: 179
A317: #NowPlaying | B317: 0.093810967 | C317: 172
B318: 0.04721497 | C318: 83
B319: 0.14080798 | C319: 235
A320: #SoundtrackOfLife | B320: 0.06425564 | C320: 95
B321: 0.15347656 | C321: 90
B322: 0.043543867 | C322: 230
A323: #NowPlaying | B323: 0.19548583 | C323: 84
A324: #SoundtrackOfLife | B324: 0.080047619 | C324: 103
B325: 0.11026748 | C325: 174
A326: #SoundtrackOfLife | B326: 0.081036535 | C326: 232
A327: #MusicForEveryone | B327: 0.051734114 | C327: 147
A328: #NowPlaying | B328: 0.1136305 | C328: 268
...

Sheet Task_2_Analysis
A1: Top 10 Posts by Engagement Rate
A2: Post ID | B2: Platform | C2: Date | D2: Content Type | E2: Post Text | F2: Likes | G2: Shares | H2: Comments | I2: Impressions | J2: Reach | K2: Clicks | L2: Hashtag 1 | M2: Hashtag 2 | N2: Campaign_Name | O2: Engagement Rate
A3: SP007 | B3: Twitter | C3: 45645 | D3: Story | E3: Get into the groove with our new drop! | F3: 4674 | G3: 409 | H3: 327 | I3: 20756 | J3: 63599 | K3: 212 | L3: #SoundtrackOfLife | M3: #NowPlaying | N3: ChillVibes | O3: 0.26064752
A4: SP106 | B4: Twitter | C4: 45677 | D4: Story | E4: New music just dropped. Hit play! | F4: 4619 | G4: 272 | H4: 57 | I4: 21334 | J4: 46292 | K4: 91 | L4: #SoundtrackOfLife | M4: #NowPlaying | N4: ChillVibes | O4: 0.23193025
A5: SP186 | B5: Twitter | C5: 45459 | D5: Story | E5: Explore the latest podcasts now. | F5: 4618 | G5: 312 | H5: 254 | I5: 22571 | J5: 29453 | K5: 197 | L5: #MusicForEveryone | M5: #NowPlaying | N5: ChillVibes | O5: 0.22967525
A6: SP279 | B6: Twitter | C6: 45676 | D6: Story | E6: New music just dropped. Hit play! | F6: 3507 | G6: 295 | H6: 371 | I6: 20410 | J6: 53965 | K6: 212 | L6: #SoundtrackOfLife | M6: #NowPlaying | N6: ChillVibes | O6: 0.2044586
A7: SP050 | B7: Twitter | C7: 45769 | D7: Text | E7: Discover fresh beats on Spotify! | F7: 4401 | G7: 421 | H7: 216 | I7: 24890 | J7: 54361 | K7: 148 | L7: #NowPlaying | N7: ChillVibes | O7: 0.20241061
A8: SP022 | B8: Instagram | C8: 45823 | D8: Text | E8: Whatâ€™s your vibe today? #SpotifyHits | F8: 4896 | G8: 466 | H8: 233 | I8: 28621 | J8: 34270 | K8: 84 | L8: #SoundtrackOfLife | M8: #NowPlaying | N8: ChillVibes | O8: 0.19548583
A9: SP157 | B9: YouTube | C9: 45718 | D9: Text | E9: From pop to podcasts, itâ€™s all here. | F9: 4425 | G9: 185 | H9: 162 | I9: 24610 | J9: 21342 | K9: 158 | L9: #DiscoverWeekly | M9: #SpotifyWrapped | N9: IndieWave | O9: 0.19390492
A10: SP248 | B10: YouTube | C10: 45457 | D10: Reel | E10: Wrapped is here! Relive your top tracks ðŸŽ§ | F10: 4722 | G10: 310 | H10: 344 | I10: 27911 | J10: 19000 | K10: 225 | L10: #DiscoverWeekly | M10: #SoundtrackOfLife | N10: SummerBeats | O10: 0.19261223
A11: SP136 | B11: Twitter | C11: 45615 | D11: Text | E11: Top trending tracks updated daily! | F11: 3728 | G11: 271 | H11: 275 | I11: 22827 | J11: 37034 | K11: 199 | L11: #NowPlaying | N11: ChillVibes | O11: 0.18723442
A12: SP068 | B12: Twitter | C12: 45379 | D12: Text | E12: Music that moves youâ€”only on Spotify. | F12: 3276 | G12: 421 | H12: 114 | I12: 20580 | J12: 30324 | K12: 221 | L12: #SoundtrackOfLife | N12: IndieWave | O12: 0.18517979
A20: Total Likes, Shares, and Comments by Platform and Content Type
A21: Platform / Content Type | B21: Sum of Likes | C21: Sum of Shares | D21: Sum of Comments
A22: Instagram | B22: 251473 | C22: 29285 | D22: 20818
A23: Story | B23: 61815 | C23: 7993 | D23: 5656
A24: Text | B24: 189658 | C24: 21292 | D24: 15162
A25: Twitter | B25: 450295 | C25: 45498 | D25: 31577
A26: Story | B26: 272103 | C26: 26494 | D26: 18442
A27: Text | B27: 178192 | C27: 19004 | D27: 13135
A28: YouTube | B28: 195407 | C28: 18618 | D28: 14671
A29: Reel | B29: 89871 | C29: 9086 | D29: 6826
A30: Text | B30: 105536 | C30: 9532 | D30: 7845
A31: Grand Total | B31: 897175 | C31: 93401 | D31: 67066
A48: Average Clicks per post by Hashtag
A49: Hashtags | B49: Average of Clicks
A50: #DiscoverWeekly | B50: 197.16923
A51: #MusicForEveryone | B51: 183.47761
A52: #NowPlaying | B52: 186.72028
A53: #SoundtrackOfLife | B53: 192.45872
A54: #SpotifyWrapped | B54: 208.47059
A55: Grand Total | B55: 191.9089
A72: Top-Performing Hashtags
A73: Hashtags | B73: Average of Clicks | C73: Rank
A74: #SpotifyWrapped | B74: 208.47059 | C74: =RANK(B74, $B$74:$B$78) -> 1
A75: #DiscoverWeekly | B75: 197.16923 | C75: =RANK(B75, $B$74:$B$78) -> 2
A76: #SoundtrackOfLife | B76: 192.45872 | C76: =RANK(B76, $B$74:$B$78) -> 3
A77: #NowPlaying | B77: 186.72028 | C77: =RANK(B77, $B$74:$B$78) -> 4
A78: #MusicForEveryone | B78: 183.47761 | C78: =RANK(B78, $B$74:$B$78) -> 5
A79: Grand Total | B79: 191.9089

Sheet Task_2_Engagement_Rate
A1: Post ID | B1: Platform | C1: Date | D1: Content Type | E1: Post Text | F1: Likes | G1: Shares | H1: Comments | I1: Impressions | J1: Reach | K1: Clicks | L1: Hashtag 1 | M1: Hashtag 2 | N1: Campaign_Name | O1: Engagement Rate
A2: SP001 | B2: Instagram | C2: 45781 | D2: Text | E2: Discover fresh beats on Spotify! | F2: 2414 | G2: 245 | H2: 137 | I2: 21181 | J2: 45292 | K2: 133 | L2: #SoundtrackOfLife | M2: #NowPlaying | N2: ChillVibes | O2: 0.1320051
A3: SP002 | B3: Instagram | C3: 45689 | D3: Text | E3: Explore the latest podcasts now. | F3: 1934 | G3: 210 | H3: 393 | I3: 29129 | J3: 73287 | K3: 273 | L3: #DiscoverWeekly | N3: IndieWave | O3: 0.087095335
A4: SP003 | B4: Twitter | C4: 45629 | D4: Story | E4: New music just dropped. Hit play! | F4: 3092 | G4: 177 | H4: 81 | I4: 47533 | J4: 29220 | K4: 121 | L4: #MusicForEveryone | M4: #NowPlaying | N4: ChillVibes | O4: 0.070477353
A5: SP004 | B5: Instagram | C5: 45629 | D5: Text | E5: Wrapped is here! Relive your top tracks ðŸŽ§ | F5: 3173 | G5: 229 | H5: 197 | I5: 29604 | J5: 21809 | K5: 272 | L5: #SoundtrackOfLife | M5: #NowPlaying | N5: ChillVibes | O5: 0.12157141
A6: SP005 | B6: YouTube | C6: 45388 | D6: Text | E6: Music that moves youâ€”only on Spotify. | F6: 2748 | G6: 145 | H6: 315 | I6: 24401 | J6: 61182 | K6: 200 | L6: #DiscoverWeekly | M6: #SpotifyWrapped | N6: IndieWave | O6: 0.13147002
A7: SP006 | B7: YouTube | C7: 45456 | D7: Text | E7: Whatâ€™s your vibe today? #SpotifyHits | F7: 3882 | G7: 239 | H7: 275 | I7: 58748 | J7: 44646 | K7: 149 | L7: #DiscoverWeekly | M7: #SpotifyWrapped | N7: IndieWave | O7: 0.074828079
A8: SP007 | B8: Twitter | C8: 45645 | D8: Story | E8: Get into the groove with our new drop! | F8: 4674 | G8: 409 | H8: 327 | I8: 20756 | J8: 63599 | K8: 212 | L8: #SoundtrackOfLife | M8: #NowPlaying | N8: ChillVibes | O8: 0.26064752
A9: SP008 | B9: Twitter | C9: 45421 | D9: Story | E9: Wrapped is here! Relive your top tracks ðŸŽ§ | F9: 1428 | G9: 347 | H9: 67 | I9: 21148 | J9: 19712 | K9: 120 | L9: #DiscoverWeekly | M9: #MusicForEveryone | N9: ChillVibes | O9: 0.087100435
A10: SP009 | B10: Twitter | C10: 45823 | D10: Text | E10: Top trending tracks updated daily! | F10: 4432 | G10: 223 | H10: 299 | I10: 59016 | J10: 21742 | K10: 171 | L10: #NowPlaying | N10: ChillVibes | O10: 0.083943337
A11: SP010 | B11: Twitter | C11: 45630 | D11: Text | E11: Wrapped is here! Relive your top tracks ðŸŽ§ | F11: 2357 | G11: 274 | H11: 172 | I11: 21566 | J11: 66829 | K11: 284 | L11: #NowPlaying | N11: ChillVibes | O11: 0.12997311
A12: SP011 | B12: Twitter | C12: 45357 | D12: Text | E12: Discover fresh beats on Spotify! | F12: 1971 | G12: 370 | H12: 306 | I12: 31316 | J12: 27897 | K12: 88 | L12: #SoundtrackOfLife | N12: IndieWave | O12: 0.084525482
A13: SP012 | B13: Instagram | C13: 45426 | D13: Text | E13: Discover fresh beats on Spotify! | F13: 1485 | G13: 353 | H13: 244 | I13: 38419 | J13: 38556 | K13: 86 | L13: #SoundtrackOfLife | M13: #NowPlaying | N13: ChillVibes | O13: 0.054191936
A14: SP013 | B14: Twitter | C14: 45826 | D14: Story | E14: Discover fresh beats on Spotify! | F14: 3956 | G14: 319 | H14: 61 | I14: 58162 | J14: 28720 | K14: 213 | L14: #MusicForEveryone | M14: #NowPlaying | N14: ChillVibes | O14: 0.074550394
A15: SP014 | B15: Twitter | C15: 45573 | D15: Text | E15: From pop to podcasts, itâ€™s all here. | F15: 2460 | G15: 409 | H15: 253 | I15: 36702 | J15: 46122 | K15: 264 | L15: #NowPlaying | N15: ChillVibes | O15: 0.085063484
A16: SP015 | B16: Twitter | C16: 45418 | D16: Text | E16: Your weekend playlist is waiting. | F16: 3476 | G16: 355 | H16: 396 | I16: 37492 | J16: 27285 | K16: 179 | L16: #NowPlaying | N16: ChillVibes | O16: 0.11274405
A17: SP016 | B17: Twitter | C17: 45655 | D17: Story | E17: New music just dropped. Hit play! | F17: 4049 | G17: 377 | H17: 94 | I17: 48182 | J17: 42875 | K17: 172 | L17: #MusicForEveryone | M17: #NowPlaying | N17: ChillVibes | O17: 0.093810967
A18: SP017 | B18: Twitter | C18: 45453 | D18: Text | E18: Whatâ€™s your vibe today? #SpotifyHits | F18: 1514 | G18: 164 | H18: 275 | I18: 41364 | J18: 44389 | K18: 83 | L18: #NowPlaying | N18: ChillVibes | O18: 0.04721497
A19: SP018 | B19: Instagram | C19: 45325 | D19: Story | E19: Music that moves youâ€”only on Spotify. | F19: 4281 | G19: 101 | H19: 163 | I19: 32278 | J19: 53382 | K19: 235 | L19: #NowPlaying | N19: Wrapped2024 | O19: 0.14080798
A20: SP019 | B20: YouTube | C20: 45458 | D20: Reel | E20: Get into the groove with our new drop! | F20: 1751 | G20: 143 | H20: 151 | I20: 31826 | J20: 47729 | K20: 95 | L20: #DiscoverWeekly | M20: #SoundtrackOfLife | N20: SummerBeats | O20: 0.06425564
A21: SP020 | B21: Instagram | C21: 45478 | D21: Text | E21: Your weekend playlist is waiting. | F21: 3753 | G21: 411 | H21: 308 | I21: 29138 | J21: 27678 | K21: 90 | L21: #DiscoverWeekly | N21: IndieWave | O21: 0.15347656
A22: SP021 | B22: Instagram | C22: 45603 | D22: Story | E22: Wrapped is here! Relive your top tracks ðŸŽ§ | F22: 1678 | G22: 423 | H22: 323 | I22: 55668 | J22: 37945 | K22: 230 | L22: #NowPlaying | N22: Wrapped2024 | O22: 0.043543867
A23: SP022 | B23: Instagram | C23: 45823 | D23: Text | E23: Whatâ€™s your vibe today? #SpotifyHits | F23: 4896 | G23: 466 | H23: 233 | I23: 28621 | J23: 34270 | K23: 84 | L23: #SoundtrackOfLife | M23: #NowPlaying | N23: ChillVibes | O23: 0.19548583
A24: SP023 | B24: YouTube | C24: 45452 | D24: Reel | E24: From pop to podcasts, itâ€™s all here. | F24: 2786 | G24: 368 | H24: 208 | I24: 42000 | J24: 39967 | K24: 103 | L24: #DiscoverWeekly | M24: #SoundtrackOfLife | N24: SummerBeats | O24: 0.080047619
A25: SP024 | B25: Twitter | C25: 45583 | D25: Text | E25: New music just dropped. Hit play! | F25: 2607 | G25: 379 | H25: 180 | I25: 28712 | J25: 61620 | K25: 174 | L25: #SoundtrackOfLife | N25: IndieWave | O25: 0.11026748
A26: SP025 | B26: YouTube | C26: 45575 | D26: Reel | E26: From pop to podcasts, itâ€™s all here. | F26: 4013 | G26: 320 | H26: 92 | I26: 54605 | J26: 60169 | K26: 232 | L26: #DiscoverWeekly | M26: #SoundtrackOfLife | N26: SummerBeats | O26: 0.081036535
A27: SP026 | B27: Twitter | C27: 45791 | D27: Story | E27: From pop to podcasts, itâ€™s all here. | F27: 2707 | G27: 103 | H27: 51 | I27: 55302 | J27: 18801 | K27: 147 | L27: #DiscoverWeekly | M27: #MusicForEveryone | N27: ChillVibes | O27: 0.051734114
A28: SP027 | B28: Instagram | C28: 45625 | D28: Text | E28: Whatâ€™s your vibe today? #SpotifyHits | F28: 2824 | G28: 425 | H28: 274 | I28: 31004 | J28: 53488 | K28: 268 | L28: #SoundtrackOfLife | M28: #NowPlaying | N28: ChillVibes | O28: 0.1136305
A29: SP028 | B29: YouTube | C29: 45356 | D29: Reel | E29: Explore the latest podcasts now. | F29: 3558 | G29: 314 | H29: 199 | I29: 49612 | J29: 53929 | K29: 206 | L29: #DiscoverWeekly | M29: #SoundtrackOfLife | N29: SummerBeats | O29: 0.08205676
A30: SP029 | B30: Twitter | C30: 45734 | D30: Story | E30: Explore the latest podcasts now. | F30: 3418 | G30: 188 | H30: 387 | I30: 57431 | J30: 36933 | K30: 202 | L30: #MusicForEveryone | M30: #NowPlaying | N30: ChillVibes | O30: 0.069526911
A31: SP030 | B31: Twitter | C31: 45773 | D31: Text | E31: Discover fresh beats on Spotify! | F31: 2411 | G31: 194 | H31: 168 | I31: 26665 | J31: 71699 | K31: 197 | L31: #NowPlaying | N31: ChillVibes | O31: 0.103994
A32: SP031 | B32: Instagram | C32: 45658 | D32: Text | E32: New music just dropped. Hit play! | F32: 4036 | G32: 112 | H32: 382 | I32: 56284 | J32: 29440 | K32: 279 | L32: #SoundtrackOfLife | M32: #NowPlaying | N32: ChillVibes | O32: 0.080484685
A33: SP032 | B33: Twitter | C33: 45419 | D33: Story | E33: Explore the latest podcasts now. | F33: 2776 | G33: 307 | H33: 178 | I33: 43365 | J33: 48408 | K33: 138 | L33: #SoundtrackOfLife | M33: #NowPlaying | N33: ChillVibes | O33: 0.075198893
A34: SP033 | B34: Twitter | C34: 45574 | D34: Story | E34: Discover fresh beats on Spotify! | F34: 4929 | G34: 182 | H34: 95 | I34: 32181 | J34: 31084 | K34: 289 | L34: #DiscoverWeekly | M34: #MusicForEveryone | N34: ChillVibes | O34: 0.16177247
A35: SP034 | B35: Instagram | C35: 45666 | D35: Text | E35: New music just dropped. Hit play! | F35: 1015 | G35: 366 | H35: 308 | I35: 38127 | J35: 63790 | K35: 287 | L35: #SoundtrackOfLife | M35: #NowPlaying | N35: ChillVibes | O35: 0.044299315
A36: SP035 | B36: Twitter | C36: 45785 | D36: Story | E36: Your weekend playlist is waiting. | F36: 3316 | G36: 332 | H36: 268 | I36: 40095 | J36: 36913 | K36: 265 | L36: #MusicForEveryone | M36: #NowPlaying | N36: ChillVibes | O36: 0.097668038
A37: SP036 | B37: Instagram | C37: 45416 | D37: Text | E37: Wrapped is here! Relive your top tracks ðŸŽ§ | F37: 2274 | G37: 243 | H37: 222 | I37: 43066 | J37: 59174 | K37: 80 | L37: #DiscoverWeekly | N37: IndieWave | O37: 0.063600056
A38: SP037 | B38: Twitter | C38: 45804 | D38: Story | E38: Explore the latest podcasts now. | F38: 4095 | G38: 385 | H38: 400 | I38: 45300 | J38: 31795 | K38: 80 | L38: #MusicForEveryone | M38: #NowPlaying | N38: ChillVibes | O38: 0.10772627
A39: SP038 | B39: Instagram | C39: 45545 | D39: Story | E39: New music just dropped. Hit play! | F39: 1230 | G39: 309 | H39: 207 | I39: 44629 | J39: 40699 | K39: 195 | L39: #NowPlaying | N39: Wrapped2024 | O39: 0.039122544
A40: SP039 | B40: Instagram | C40: 45621 | D40: Text | E40: From pop to podcasts, itâ€™s all here. | F40: 1341 | G40: 472 | H40: 238 | I40: 51386 | J40: 51706 | K40: 133 | L40: #DiscoverWeekly | N40: IndieWave | O40: 0.039913595
...

Sheet All_Task_3_Analysis
A1: Average Engagement Rate by Platform
A2: Platform | B2: Average of Engagement_Rate
A3: Twitter | B3: 6.8856716
A4: YouTube | B4: 6.7189394
A5: Instagram | B5: 6.458209
A6: Grand Total | B6: 6.68745
A24: Platform-wise Weekly Growth Rate Analysis
A25: Average of Growth Rate % | B25: Platform
A26: Week_Start_Date | B26: Instagram | C26: Twitter | D26: YouTube | E26: Grand Total
A27: 45446 | B27: 0.010709526 | C27: 0.0039875767 | D27: 0.0031763009 | E27: 0.0059578012
A28: 45453 | B28: 0.010035253 | C28: 0.0042474658 | D28: 0.0011541771 | E28: 0.005145632
A29: 45460 | B29: 0.0061532044 | C29: 0.005216571 | D29: 0.0051990991 | E29: 0.0055229582
A30: 45467 | B30: 0.0070194756 | C30: 0.0087155963 | D30: 0.0055548943 | E30: 0.0070966554
A31: 45474 | B31: 0.0039974246 | C31: 0.0027265062 | D31: 0.0037184126 | E31: 0.0034807812
A32: 45481 | B32: 0.0019610668 | C32: 0.017836234 | D32: 0.0057836391 | E32: 0.0085269801
A33: 45488 | B33: 0.0021159343 | C33: 0.0041633647 | D33: 0.0044074792 | E33: 0.0035622594
A34: 45495 | B34: 0.0038800515 | C34: 0.0013666229 | D34: 0.0029558126 | E34: 0.0027341623
A35: 45502 | B35: 0.0023089718 | C35: 0.0052125958 | D35: 0.0024107128 | E35: 0.0033107601
A36: 45509 | B36: 0.0067435555 | C36: 0.0043839826 | D36: 0.0023829134 | E36: 0.0045034839
A37: 45516 | B37: 0.014216285 | C37: 0.010311242 | D37: 0.0032668165 | E37: 0.0092647813
A38: 45523 | B38: 0.0025711522 | C38: 0.006216942 | D38: 0.0061138546 | E38: 0.0049673163
... A92: 45901 | B92: 0.0031996008 | C92: 0.003671063 | D92: 0.00079729049 | E92: 0.0025559848
A93: 45908 | B93: 0.0091194199 | C93: 0.0017666324 | E93: 0.0054430262
A94: Grand Total | B94: 0.0043506104 | C94: 0.0046999265 | D94: 0.0039495608 | E94: 0.0043352849
A103: Ad Spend vs. Engagement Rate Analysis by Platform
A104: Platform | B104: Sum of Ad_Spend | C104: Average of Engagement_Rate
A105: Instagram | B105: 1035942 | C105: 6.458209
A106: Twitter | B106: 1114204 | C106: 6.8856716
A107: YouTube | B107: 1065782 | C107: 6.7189394
A108: Grand Total | B108: 3215928 | C108: 6.68745

Sheet All_Task_4_Analysis
A3: Most Frequent Hashtags and Average Engagement
A4: Hashtags | B4: Count of All_Hashtags | C4: Average of Engagement Rate
A5: #NowPlaying | B5: 143 | C5: 0.098567431
A6: #DiscoverWeekly | B6: 130 | C6: 0.087606633
A7: #SoundtrackOfLife | B7: 109 | C7: 0.09444867
A8: #MusicForEveryone | B8: 67 | C8: 0.089057449
A9: #SpotifyWrapped | B9: 34 | C9: 0.086403291
A10: Grand Total | B10: 483 | C10: 0.092512362
A27: Content Type Performance Across Platforms
A28: Average of Engagement Rate | B28: Platform
A29: Content Type | B29: Instagram | C29: Twitter | D29: YouTube | E29: Grand Total
A30: Reel | D30: 0.090106882 | E30: 0.090106882
A31: Story | B31: 0.095509124 | C31: 0.096350204 | E31: 0.096174342
A32: Text | B32: 0.089151971 | C32: 0.095584491 | D32: 0.086403291 | E32: 0.09100867
A33: Grand Total | B33: 0.09079483 | C33: 0.096034606 | D33: 0.088108119 | E33: 0.092815577

Sheet All_Task_5_Analysis
A1: Total & Average Impressions, Likes, Clicks Per Campaign
A2: Campaign_Name | B2: Start_Date | C2: End_Date | D2: Sum of Impressions | E2: Avg of Impressions | F2: Sum of Likes | G2: Avg of Likes | H2: Sum of Clicks | I2: Avg of Clicks
A3: ChillVibes | B3: 45667 | C3: 45698 | D3: =SUMIFS(Posts!I:I, Posts!N:N, A3, Posts!C:C, ">="&B3, Posts!C:C, "<="&C3) -> 378559 | E3: =AVERAGEIFS(Posts!I:I, Posts!N:N, A3, Posts!C:C, ">="&B3, Posts!C:C, "<="&C3) -> 34414.455 | F3: =SUMIFS(Posts!F:F, Posts!N:N, A3, Posts!C:C, ">="&B3, Posts!C:C, "<="&C3) -> 34980 | G3: =AVERAGEIFS(Posts!F:F, Posts!N:N, A3, Posts!C:C, ">="&B3, Posts!C:C, "<="&C3) -> 3180 | H3: =SUMIFS(Posts!K:K, Posts!N:N, A3, Posts!C:C, ">="&B3, Posts!C:C, "<="&C3) -> 2232 | I3: =AVERAGEIFS(Posts!K:K, Posts!N:N, A3, Posts!C:C, ">="&B3, Posts!C:C, "<="&C3) -> 202.90909
A4: IndieWave | B4: 45717 | C4: 45747 | D4: =SUMIFS(Posts!I:I, Posts!N:N, A4, Posts!C:C, ">="&B4, Posts!C:C, "<="&C4) -> 262944 | E4: =AVERAGEIFS(Posts!I:I, Posts!N:N, A4, Posts!C:C, ">="&B4, Posts!C:C, "<="&C4) -> 43824 | F4: =SUMIFS(Posts!F:F, Posts!N:N, A4, Posts!C:C, ">="&B4, Posts!C:C, "<="&C4) -> 23692 | G4: =AVERAGEIFS(Posts!F:F, Posts!N:N, A4, Posts!C:C, ">="&B4, Posts!C:C, "<="&C4) -> 3948.6667 | H4: =SUMIFS(Posts!K:K, Posts!N:N, A4, Posts!C:C, ">="&B4, Posts!C:C, "<="&C4) -> 1370 | I4: =AVERAGEIFS(Posts!K:K, Posts!N:N, A4, Posts!C:C, ">="&B4, Posts!C:C, "<="&C4) -> 228.33333
A5: SummerBeats | B5: 45458 | C5: 45488 | D5: =SUMIFS(Posts!I:I, Posts!N:N, A5, Posts!C:C, ">="&B5, Posts!C:C, "<="&C5) -> 88805 | E5: =AVERAGEIFS(Posts!I:I, Posts!N:N, A5, Posts!C:C, ">="&B5, Posts!C:C, "<="&C5) -> 44402.5 | F5: =SUMIFS(Posts!F:F, Posts!N:N, A5, Posts!C:C, ">="&B5, Posts!C:C, "<="&C5) -> 6372 | G5: =AVERAGEIFS(Posts!F:F, Posts!N:N, A5, Posts!C:C, ">="&B5, Posts!C:C, "<="&C5) -> 3186 | H5: =SUMIFS(Posts!K:K, Posts!N:N, A5, Posts!C:C, ">="&B5, Posts!C:C, "<="&C5) -> 300 | I5: =AVERAGEIFS(Posts!K:K, Posts!N:N, A5, Posts!C:C, ">="&B5, Posts!C:C, "<="&C5) -> 150
A6: Wrapped2024 | B6: 45627 | C6: 45657 | D6: =SUMIFS(Posts!I:I, Posts!N:N, A6, Posts!C:C, ">="&B6, Posts!C:C, "<="&C6) -> 103517 | E6: =AVERAGEIFS(Posts!I:I, Posts!N:N, A6, Posts!C:C, ">="&B6, Posts!C:C, "<="&C6) -> 51758.5 | F6: =SUMIFS(Posts!F:F, Posts!N:N, A6, Posts!C:C, ">="&B6, Posts!C:C, "<="&C6) -> 8375 | G6: =AVERAGEIFS(Posts!F:F, Posts!N:N, A6, Posts!C:C, ">="&B6, Posts!C:C, "<="&C6) -> 4187.5 | H6: =SUMIFS(Posts!K:K, Posts!N:N, A6, Posts!C:C, ">="&B6, Posts!C:C, "<="&C6) -> 253 | I6: =AVERAGEIFS(Posts!K:K, Posts!N:N, A6, Posts!C:C, ">="&B6, Posts!C:C, "<="&C6) -> 126.5
A41: Engagement uplift during vs. before campaign
A42: Campaign_Name | B42: Start_Date | C42: End_Date | D42: Avg_During_Campaign | E42: Avg_Before_Campaign | F42: Uplift %
A43: ChillVibes | B43: 45667 | C43: 45698 | D43: =AVERAGEIFS(Posts!O:O,Posts!N:N, A43, Posts!C:C, ">="&B43, Posts!C:C, "<="&C43) -> 0.1208618 | E43: =AVERAGEIFS(Posts!O:O, Posts!N:N, A43, Posts!C:C, ">="&B43-30,Posts!C:C, "<"&B43) -> 0.11129033 | F43: =(D43-E43)/E43 -> 0.086004489
A44: IndieWave | B44: 45717 | C44: 45747 | D44: =AVERAGEIFS(Posts!O:O,Posts!N:N, A44, Posts!C:C, ">="&B44, Posts!C:C, "<="&C44) -> 0.11095871 | E44: =AVERAGEIFS(Posts!O:O, Posts!N:N, A44, Posts!C:C, ">="&B44-30,Posts!C:C, "<"&B44) -> 0.087095335 | F44: =(D44-E44)/E44 -> 0.27399146
A45: SummerBeats | B45: 45458 | C45: 45488 | D45: =AVERAGEIFS(Posts!O:O,Posts!N:N, A45, Posts!C:C, ">="&B45, Posts!C:C, "<="&C45) -> 0.078574757 | E45: =AVERAGEIFS(Posts!O:O, Posts!N:N, A45, Posts!C:C, ">="&B45-30,Posts!C:C, "<"&B45) -> 0.092378671 | F45: =(D45-E45)/E45 -> -0.14942751
A46: Wrapped2024 | B46: 45627 | C46: 45657 | D46: =AVERAGEIFS(Posts!O:O,Posts!N:N, A46, Posts!C:C, ">="&B46, Posts!C:C, "<="&C46) -> 0.095604953 | E46: =AVERAGEIFS(Posts!O:O, Posts!N:N, A46, Posts!C:C, ">="&B46-30,Posts!C:C, "<"&B46) -> 0.043543867 | F46: =(D46-E46)/E46 -> 1.1956009
A63: Campaign with highest ROI
A64: Campaign_Name | B64: Start_Date | C64: End_Date | D64: Total Likes | E64: Total Comments | F64: Total Shares | G64: Total Clicks | H64: Total Engagement | I64: Total Ad_Spend | J64: ROI
A65: ChillVibes | B65: 45667 | C65: 45698 | D65: =SUMIFS(Posts!F:F, Posts!N:N, A65, Posts!C:C, ">="&B65, Posts!C:C, "<="&C65) -> 34980 | E65: =SUMIFS(Posts!H:H, Posts!N:N, A65, Posts!C:C, ">="&B65, Posts!C:C, "<="&C65) -> 1712 | F65: =SUMIFS(Posts!G:G, Posts!N:N, A65, Posts!C:C, ">="&B65, Posts!C:C, "<="&C65) -> 3681 | G65: =SUMIFS(Posts!K:K, Posts!N:N, A65, Posts!C:C, ">="&B65, Posts!C:C, "<="&C65) -> 2232 | H65: =D65+E65+F65+G65 -> 42605 | I65: =SUMIFS('Engagement Summary'!G:G, 'Engagement Summary'!A:A, ">="&B65, 'Engagement Summary'!A:A, "<="&C65) -> 201460 | J65: =H65/I65 -> 0.21148119
A66: IndieWave | B66: 45717 | C66: 45747 | D66: =SUMIFS(Posts!F:F, Posts!N:N, A66, Posts!C:C, ">="&B66, Posts!C:C, "<="&C66) -> 23692 | E66: =SUMIFS(Posts!H:H, Posts!N:N, A66, Posts!C:C, ">="&B66, Posts!C:C, "<="&C66) -> 1433 | F66: =SUMIFS(Posts!G:G, Posts!N:N, A66, Posts!C:C, ">="&B66, Posts!C:C, "<="&C66) -> 1948 | G66: =SUMIFS(Posts!K:K, Posts!N:N, A66, Posts!C:C, ">="&B66, Posts!C:C, "<="&C66) -> 1370 | H66: =D66+E66+F66+G66 -> 28443 | I66: =SUMIFS('Engagement Summary'!G:G, 'Engagement Summary'!A:A, ">="&B66, 'Engagement Summary'!A:A, "<="&C66) -> 246330 | J66: =H66/I66 -> 0.11546706
A67: SummerBeats | B67: 45458 | C67: 45488 | D67: =SUMIFS(Posts!F:F, Posts!N:N, A67, Posts!C:C, ">="&B67, Posts!C:C, "<="&C67) -> 6372 | E67: =SUMIFS(Posts!H:H, Posts!N:N, A67, Posts!C:C, ">="&B67, Posts!C:C, "<="&C67) -> 449 | F67: =SUMIFS(Posts!G:G, Posts!N:N, A67, Posts!C:C, ">="&B67, Posts!C:C, "<="&C67) -> 517 | G67: =SUMIFS(Posts!K:K, Posts!N:N, A67, Posts!C:C, ">="&B67, Posts!C:C, "<="&C67) -> 300 | H67: =D67+E67+F67+G67 -> 7638 | I67: =SUMIFS('Engagement Summary'!G:G, 'Engagement Summary'!A:A, ">="&B67, 'Engagement Summary'!A:A, "<="&C67) -> 252741 | J67: =H67/I67 -> 0.030220661
A68: Wrapped2024 | B68: 45627 | C68: 45657 | D68: =SUMIFS(Posts!F:F, Posts!N:N, A68, Posts!C:C, ">="&B68, Posts!C:C, "<="&C68) -> 8375 | E68: =SUMIFS(Posts!H:H, Posts!N:N, A68, Posts!C:C, ">="&B68, Posts!C:C, "<="&C68) -> 452 | F68: =SUMIFS(Posts!G:G, Posts!N:N, A68, Posts!C:C, ">="&B68, Posts!C:C, "<="&C68) -> 719 | G68: =SUMIFS(Posts!K:K, Posts!N:N, A68, Posts!C:C, ">="&B68, Posts!C:C, "<="&C68) -> 253 | H68: =D68+E68+F68+G68 -> 9799 | I68: =SUMIFS('Engagement Summary'!G:G, 'Engagement Summary'!A:A, ">="&B68, 'Engagement Summary'!A:A, "<="&C68) -> 243827 | J68: =H68/I68 -> 0.04018833
A98: Campaign with strongest follower
A99: Campaign_Name | B99: Start_Date | C99: End_Date | D99: Total Follower Gain
A100: ChillVibes | B100: 45667 | C100: 45698 | D100: =SUMIFS('Engagement Summary'!H:H,'Engagement Summary'!A:A, ">="&B100, 'Engagement Summary'!A:A, "<="&C100) -> 10142
A101: IndieWave | B101: 45717 | C101: 45747 | D101: =SUMIFS('Engagement Summary'!H:H,'Engagement Summary'!A:A, ">="&B101, 'Engagement Summary'!A:A, "<="&C101) -> 12726
A102: SummerBeats | B102: 45458 | C102: 45488 | D102: =SUMIFS('Engagement Summary'!H:H,'Engagement Summary'!A:A, ">="&B102, 'Engagement Summary'!A:A, "<="&C102) -> 13558
A103: Wrapped2024 | B103: 45627 | C103: 45657 | D103: =SUMIFS('Engagement Summary'!H:H,'Engagement Summary'!A:A, ">="&B103, 'Engagement Summary'!A:A, "<="&C103) -> 11361
A104: Grand Total | D104: =SUM(D100:D103) -> 47787

Sheet All_Task_6_Analysis
A2: Week with Highest Net Follower Gain
A3: Week_Start_Date | B3: Sum of Net Follower Gain
A4: 45600 | B4: 3576
A5: 45796 | B5: 3569
A6: 45446 | B6: 3419
A7: 45754 | B7: 3291
A8: 45866 | B8: 3236
A9: 45761 | B9: 3216
A10: 45460 | B10: 3175
A11: 45481 | B11: 3155
A12: 45565 | B12: 3151
A13: 45516 | B13: 3072
A14: 45803 | B14: 2909
A15: 45607 | B15: 2794
... A70: 45831 | B70: 1384
A71: Grand Total | B71: 161588
A78: 3-Week Moving Average to Analyze Follower Trends
A79: Week_Start_Date | B79: Sum of Net Follower Gain | C79: 3-Week Moving Average
A80: 45446 | B80: 3419
A81: 45453 | B81: 2777
A82: 45460 | B82: 3175 | C82: =AVERAGE(B80:B82) -> 3123.6667
A83: 45467 | B83: 2433 | C83: =AVERAGE(B81:B83) -> 2795
A84: 45474 | B84: 2426 | C84: =AVERAGE(B82:B84) -> 2678
A85: 45481 | B85: 3155 | C85: =AVERAGE(B83:B85) -> 2671.3333
A86: 45488 | B86: 2369 | C86: =AVERAGE(B84:B86) -> 2650
A87: 45495 | B87: 2281 | C87: =AVERAGE(B85:B87) -> 2601.6667
A88: 45502 | B88: 2132 | C88: =AVERAGE(B86:B88) -> 2260.6667
A89: 45509 | B89: 2693 | C89: =AVERAGE(B87:B89) -> 2368.6667
A90: 45516 | B90: 3072 | C90: =AVERAGE(B88:B90) -> 2632.3333
A91: 45523 | B91: 2300 | C91: =AVERAGE(B89:B91) -> 2688.3333
A92: 45530 | B92: 2450 | C92: =AVERAGE(B90:B92) -> 2607.3333
A93: 45537 | B93: 2502 | C93: =AVERAGE(B91:B93) -> 2417.3333
... A146: 45908 | B146: 1436 | C146: =AVERAGE(B144:B146) -> 1835.3333
A147: Grand Total | B147: 161588
A153: Correlation between Ad Spend vs. Follower Growth
A154: Week_Start_Date | B154: Sum of Ad_Spend | C154: Sum of Net Follower Gain
A155: 45446 | B155: 53723 | C155: 3419
A156: 45453 | B156: 60293 | C156: 2777
A157: 45460 | B157: 51908 | C157: 3175
A158: 45467 | B158: 57474 | C158: 2433
...
